Workbook
Name TAT_Acc_D: Model!$E$16
Name TAT_Acc_EV: Model!$D$16
Name TAT_AuxBase_D: Model!$E$23
Name TAT_AuxBase_EV: Model!$D$23
Name TAT_Cal_Apply: Model!$D$38
Name TAT_CF_D: Model!$E$42
Name TAT_CF_EV: Model!$D$42
Name TAT_Crr_D: Model!$E$10
Name TAT_Crr_EV: Model!$D$10
Name TAT_Descent_Share: Model!$D$22
Name TAT_EF_Diesel: Model!$E$35
Name TAT_EF_Grid: Model!$D$34
Name TAT_EtaCharger: Model!$D$31
Name TAT_EtaEng_D: Model!$E$17
Name TAT_EtaPT_D: Model!$E$20
Name TAT_EtaPT_EV: Model!$D$20
Name TAT_G_acc: Model!$D$14
Name TAT_HVAC_k: Model!$D$24
Name TAT_HVAC_Tset: Model!$D$25
Name TAT_IdleFuel_D: Model!$E$28
Name TAT_Kaero_D: Model!$E$15
Name TAT_Kaero_EV: Model!$D$15
Name TAT_Kerb_D: Model!$E$6
Name TAT_Kerb_EV: Model!$D$6
Name TAT_L_Basis: Calc!$E$2:$E$3
Name TAT_L_Bus: Calc!$H$2:$H$3
Name TAT_L_Corr: Calc!$A$2:$A$5
Name TAT_L_Dir: OFFSET(Calc!$B$2,0,0,1+COUNTIF(Calc!$B$3:$B$8,"?*"),1)
Name TAT_L_Metric: Calc!$F$2:$F$5
Name TAT_L_Month: Calc!$C$2:$C$5
Name TAT_L_RouteCorr: Calc!$I$2:$I$4
Name TAT_L_RouteDir: Model!$B$81:$B$86
Name TAT_LHV_kWhL: Model!$E$30
Name TAT_Pax_Default: Model!$D$7
Name TAT_Pax_Mass: Model!$D$8
Name TAT_Price_Diesel: Model!$E$33
Name TAT_Regen_EV: Model!$D$21
Name TAT_Sel_Basis: Dashboard!$M$8
Name TAT_Sel_Corridor: Dashboard!$B$8
Name TAT_Sel_Direction: Dashboard!$F$8
Name TAT_Sel_DirEff: Calc!$L$2
Name TAT_Sel_Metric: Dashboard!$Q$8
Name TAT_Sel_Month: Dashboard!$J$8
Name TAT_Tariff_EV: Model!$D$32
Name TAT_Temp_Default: Model!$D$26

Sheet Calc
A1: Corridors | B1: Dependent directions | C1: Month labels | D1: Month dates | E1: Basis | F1: Trend metric | H1: Vehicles | I1: Route corridors
A2: All | B2: All | C2: All | E2: Unique trips | F2: SEC (kWh/km) | H2: EV | I2: Chennai ↔ Pondicherry | L2: =IF(OR(TAT_Sel_Direction="All",TAT_Sel_Direction=""),"All",IF(TAT_Sel_Corridor="All",TAT_Sel_Direction,IF(COUNTIFS(Routes[Corridor],TAT_Sel_Corridor,Routes[Direction],TAT_Sel_Direction)=0,"All",TAT_Sel_Direction))) -> All
A3: Chennai ↔ Pondicherry | B3: =IFERROR(INDEX(Routes[Direction],_xlfn.AGGREGATE(15,6,(ROW(Routes[Direction])-ROW(INDEX(Routes[Direction],1))+1)/(((Routes[Corridor]=TAT_Sel_Corridor)+(TAT_Sel_Corridor="All"))>0),ROWS($B$3:B3))),"") -> Maduravoyal → Silk Board | C3: =TEXT(D3,"mmm yyyy") -> Jul 2026 | D3: 46204 | E3: All pair instances | F3: Efficiency (km/kWh) | H3: Diesel | I3: Maduravoyal ↔ Madiwala | L3: =IFERROR(MATCH(TAT_Sel_Metric,$F$2:$F$5,0),1) -> 1
A4: Maduravoyal ↔ Madiwala | B4: =IFERROR(INDEX(Routes[Direction],_xlfn.AGGREGATE(15,6,(ROW(Routes[Direction])-ROW(INDEX(Routes[Direction],1))+1)/(((Routes[Corridor]=TAT_Sel_Corridor)+(TAT_Sel_Corridor="All"))>0),ROWS($B$3:B4))),"") -> Silk Board → Maduravoyal | C4: =TEXT(D4,"mmm yyyy") -> Sep 2026 | D4: 46266 | F4: Energy cost (INR/km) | I4: Maduravoyal ↔ Silk Board
A5: Maduravoyal ↔ Silk Board | B5: =IFERROR(INDEX(Routes[Direction],_xlfn.AGGREGATE(15,6,(ROW(Routes[Direction])-ROW(INDEX(Routes[Direction],1))+1)/(((Routes[Corridor]=TAT_Sel_Corridor)+(TAT_Sel_Corridor="All"))>0),ROWS($B$3:B5))),"") | C5: =TEXT(D5,"mmm yyyy") -> Oct 2026 | D5: 46296 | F5: CO2 (kg/km)
B6: =IFERROR(INDEX(Routes[Direction],_xlfn.AGGREGATE(15,6,(ROW(Routes[Direction])-ROW(INDEX(Routes[Direction],1))+1)/(((Routes[Corridor]=TAT_Sel_Corridor)+(TAT_Sel_Corridor="All"))>0),ROWS($B$3:B6))),"")
B7: =IFERROR(INDEX(Routes[Direction],_xlfn.AGGREGATE(15,6,(ROW(Routes[Direction])-ROW(INDEX(Routes[Direction],1))+1)/(((Routes[Corridor]=TAT_Sel_Corridor)+(TAT_Sel_Corridor="All"))>0),ROWS($B$3:B7))),"")
B8: =IFERROR(INDEX(Routes[Direction],_xlfn.AGGREGATE(15,6,(ROW(Routes[Direction])-ROW(INDEX(Routes[Direction],1))+1)/(((Routes[Corridor]=TAT_Sel_Corridor)+(TAT_Sel_Corridor="All"))>0),ROWS($B$3:B8))),"")
K20: Selected fleet | L20: EV | M20: Diesel
K21: Selected trips | L21: =COUNTIFS(Trips[Bus Type],"EV",Trips[Flag all],1) -> 7 | M21: =COUNTIFS(Trips[Bus Type],"Diesel",Trips[Flag all],1) -> 7
K22: Distance (km) | L22: =SUMIFS(Trips[Distance (km)],Trips[Bus Type],"EV",Trips[Flag all],1) -> 2151.3212 | M22: =SUMIFS(Trips[Distance (km)],Trips[Bus Type],"Diesel",Trips[Flag all],1) -> 2164.4612
K23: Energy consumed (kWh) | L23: =SUMIFS(Trips[Energy consumed (kWh)],Trips[Bus Type],"EV",Trips[Flag all],1) -> 2001.7465 | M23: =SUMIFS(Trips[Energy consumed (kWh)],Trips[Bus Type],"Diesel",Trips[Flag all],1) -> 5352.0533
K24: Energy consumed (MJ) | L24: =SUMIFS(Trips[Energy consumed (MJ)],Trips[Bus Type],"EV",Trips[Flag all],1) -> 7206.2875 | M24: =SUMIFS(Trips[Energy consumed (MJ)],Trips[Bus Type],"Diesel",Trips[Flag all],1) -> 19267.392
K25: Diesel consumed (L) | L25: =SUMIFS(Trips[Diesel consumed (L)],Trips[Bus Type],"EV",Trips[Flag all],1) -> 0 | M25: =SUMIFS(Trips[Diesel consumed (L)],Trips[Bus Type],"Diesel",Trips[Flag all],1) -> 536.69615
K26: EV grid energy (kWh) | L26: =SUMIFS(Trips[EV grid energy (kWh)],Trips[Bus Type],"EV",Trips[Flag all],1) -> 2175.8114 | M26: =SUMIFS(Trips[EV grid energy (kWh)],Trips[Bus Type],"Diesel",Trips[Flag all],1) -> 0
K27: Wheel energy (kWh) | L27: =SUMIFS(Trips[Wheel energy (kWh)],Trips[Bus Type],"EV",Trips[Flag all],1) -> 1550.9518 | M27: =SUMIFS(Trips[Wheel energy (kWh)],Trips[Bus Type],"Diesel",Trips[Flag all],1) -> 1444.3301
K28: Energy cost (INR) | L28: =SUMIFS(Trips[Energy cost (INR)],Trips[Bus Type],"EV",Trips[Flag all],1) -> 20670.209 | M28: =SUMIFS(Trips[Energy cost (INR)],Trips[Bus Type],"Diesel",Trips[Flag all],1) -> 49376.046
K29: CO2 (kg) | L29: =SUMIFS(Trips[CO2 (kg)],Trips[Bus Type],"EV",Trips[Flag all],1) -> 1544.8261 | M29: =SUMIFS(Trips[CO2 (kg)],Trips[Bus Type],"Diesel",Trips[Flag all],1) -> 1438.3457
K30: Operating time (h) | L30: =SUMIFS(Trips[Operating time (h)],Trips[Bus Type],"EV",Trips[Flag all],1) -> 37.867767 | M30: =SUMIFS(Trips[Operating time (h)],Trips[Bus Type],"Diesel",Trips[Flag all],1) -> 37.211617
K31: t Charging (min) | L31: =SUMIFS(Trips[t Charging (min)],Trips[Bus Type],"EV",Trips[Flag all],1) -> 206.41667 | M31: =SUMIFS(Trips[t Charging (min)],Trips[Bus Type],"Diesel",Trips[Flag all],1) -> 0
K32: Trip time incl charging (h) | L32: =SUMIFS(Trips[Trip time incl charging (h)],Trips[Bus Type],"EV",Trips[Flag all],1) -> 41.308045 | M32: =SUMIFS(Trips[Trip time incl charging (h)],Trips[Bus Type],"Diesel",Trips[Flag all],1) -> 37.211617
K33: SEC kWh/km | L33: =IFERROR(L23/L22,"") -> 0.93047311 | M33: =IFERROR(M23/M22,"") -> 2.4726954
K34: Efficiency km/kWh | L34: =IFERROR(L22/L23,"") -> 1.0747221 | M34: =IFERROR(M22/M23,"") -> 0.40441698
K35: Economy km/L | L35: ="" | M35: =IFERROR(M22/M25,"") -> 4.032936
K36: Wheel / consumed energy | L36: =IFERROR(L27/L23,"") -> 0.77479928 | M36: =IFERROR(M27/M23,"") -> 0.26986467
K37: Cost/km | L37: =IFERROR(L28/L22,"") -> 9.6081463 | M37: =IFERROR(M28/M22,"") -> 22.812165
K38: CO2/km | L38: =IFERROR(L29/L22,"") -> 0.71808251 | M38: =IFERROR(M29/M22,"") -> 0.66452827
K39: Average charging/refuel minutes | L39: =IFERROR(L31/L21,"") -> 29.488095 | M39: =IFERROR(M31/M21,"") -> 0
K40: Average trip hours | L40: =IFERROR(L32/L21,"") -> 5.9011493 | M40: =IFERROR(M32/M21,"") -> 5.3159452
K41: Average trip energy | L41: =IFERROR(L23/L21,"") -> 285.96379 | M41: =IFERROR(M23/M21,"") -> 764.57904
K42: Operating speed | L42: =IFERROR(L22/L30,"") -> 56.811408 | M42: =IFERROR(M22/M30,"") -> 58.166278
K43: Energy saving | L43: =IFERROR(1-L33/M33,"") -> 0.62370087
K44: Cost saving | L44: =IFERROR(1-L37/M37,"") -> 0.57881479
K45: CO2 saving | L45: =IFERROR(1-L38/M38,"") -> -0.080589855
K46: Efficiency multiplier | L46: =IFERROR(L34/M34,"") -> 2.6574603
K47: Full TAT difference, minutes | L47: =IF(AND(L21>0,M21>0),(L40-M40)*60,"") -> 35.112243
K48: Global measured trips | L48: =COUNTIFS(Trips[Bus Type],"EV",Trips[Measured energy (kWh eq)],">0") -> 0 | M48: =COUNTIFS(Trips[Bus Type],"Diesel",Trips[Measured energy (kWh eq)],">0") -> 0
X50: Vehicle | Y50: Road load | Z50: Acceleration | AA50: Gradient | AB50: Auxiliaries / HVAC | AC50: Engine idling | AD50: Regeneration
K51: Road load | L51: =IFERROR(1*SUMIFS(Trips[Road-load net (kWh)],Trips[Bus Type],"EV",Trips[Flag all],1)*IF(TAT_Cal_Apply="Yes",TAT_CF_EV,1)/TAT_EtaPT_EV/L$22,0) -> 0.64883535 | M51: =IFERROR(1*SUMIFS(Trips[Road-load net (kWh)],Trips[Bus Type],"Diesel",Trips[Flag all],1)*IF(TAT_Cal_Apply="Yes",TAT_CF_D,1)/TAT_EtaPT_D/M$22,0) -> 1.5217789 | X51: EV | Y51: =L51 -> 0.64883535 | Z51: =L52 -> 0.23158681 | AA51: =L53 -> -0.011151175 | AB51: =L54 -> 0.142577 | AC51: =L55 -> 0 | AD51: =L56 -> -0.081374877
K52: Acceleration | L52: =IFERROR(1*SUMIFS(Trips[Inertial energy (kWh)],Trips[Bus Type],"EV",Trips[Flag all],1)*IF(TAT_Cal_Apply="Yes",TAT_CF_EV,1)/TAT_EtaPT_EV/L$22,0) -> 0.23158681 | M52: =IFERROR(1*SUMIFS(Trips[Inertial energy (kWh)],Trips[Bus Type],"Diesel",Trips[Flag all],1)*IF(TAT_Cal_Apply="Yes",TAT_CF_D,1)/TAT_EtaPT_D/M$22,0) -> 0.57564659 | X52: Diesel | Y52: =M51 -> 1.5217789 | Z52: =M52 -> 0.57564659 | AA52: =M53 -> -0.025086617 | AB52: =M54 -> 0.36573812 | AC52: =M55 -> 0.034618393 | AD52: =M56 -> 0
...

Sheet Model
A1: Energy model and route assumptions | H1: Yes
H2: No
A3: Blue cells are editable. Defaults reproduce the reference's passenger/coach assumptions.
A5: Parameter | C5: Unit | D5: EV | E5: Diesel
A6: Kerb mass | C6: kg | D6: 13780 | E6: 11780
A7: Default passengers | C7: persons | D7: 40 | E7: =D7 -> 40
A8: Passenger mass including luggage | C8: kg/person | D8: 68 | E8: =D8 -> 68
A9: Default operating mass | C9: kg | D9: =D6+D7*D8 -> 16500 | E9: =E6+D7*D8 -> 14500
A10: Rolling resistance coefficient | C10: - | D10: 0.007 | E10: 0.007
A11: Drag coefficient | C11: - | D11: 0.65 | E11: 0.65
A12: Frontal area | C12: m² | D12: 8.2 | E12: 8.2
A13: Air density | C13: kg/m³ | D13: 1.18 | E13: =D13 -> 1.18
A14: Gravitational acceleration | C14: m/s² | D14: 9.81 | E14: =D14 -> 9.81
A15: Aerodynamic constant | C15: N/(m/s)² | D15: =0.5*D13*D11*D12 -> 3.1447 | E15: =0.5*E13*E11*E12 -> 3.1447
A16: Default mean acceleration | C16: m/s² | D16: 0.25 | E16: 0.25
A17: Motor/inverter or engine efficiency | C17: - | D17: 0.9 | E17: 0.35
A18: Driveline efficiency | C18: - | D18: 0.95 | E18: 0.92
A19: Battery discharge efficiency | C19: - | D19: 0.97
A20: Combined powertrain efficiency | C20: - | D20: =D17*D18*D19 -> 0.82935 | E20: =E17*E18 -> 0.322
A21: Regenerative recovery fraction | C21: - | D21: 0.6 | E21: 0
A22: Descent share offsetting road load | C22: - | D22: 0.5 | E22: =D22 -> 0.5
A23: Base auxiliary power | C23: kW | D23: 3 | E23: 3
A24: HVAC load above setpoint | C24: kW/°C | D24: 0.85 | E24: =D24 -> 0.85
A25: HVAC setpoint | C25: °C | D25: 24 | E25: =D25 -> 24
A26: Default ambient temperature | C26: °C | D26: 30 | E26: =D26 -> 30
A27: Auxiliary power at default temperature | C27: kW | D27: =D23+D24*MAX(0,D26-D25) -> 8.1 | E27: =E23+E24*MAX(0,E26-E25) -> 8.1
A28: Diesel idle fuel rate | C28: L/h | E28: 2.5
A29: Diesel lower heating value | C29: MJ/L | E29: 35.9
A30: Diesel lower heating value | C30: kWh/L | E30: =E29/3.6 -> 9.9722222
A31: Charger efficiency | C31: - | D31: 0.92
A32: Electricity tariff | C32: INR/kWh | D32: 9.5
A33: Diesel price | C33: INR/L | E33: 92
A34: Grid emission factor | C34: kg/kWh | D34: 0.71
A35: Diesel emission factor | C35: kg/L | E35: 2.68
A38: Apply global vehicle-type calibration? | D38: Yes
A39: Trips with positive measured consumption | D39: =COUNTIFS(Trips[Bus Type],"EV",Trips[Measured energy (kWh eq)],">0") -> 0 | E39: =COUNTIFS(Trips[Bus Type],"Diesel",Trips[Measured energy (kWh eq)],">0") -> 0
A40: Measured energy sum (kWh equivalent) | D40: =SUMIFS(Trips[Measured energy (kWh eq)],Trips[Bus Type],"EV",Trips[Measured energy (kWh eq)],">0") -> 0 | E40: =SUMIFS(Trips[Measured energy (kWh eq)],Trips[Bus Type],"Diesel",Trips[Measured energy (kWh eq)],">0") -> 0
A41: Modelled energy for the same records | D41: =SUMIFS(Trips[Modelled energy (kWh)],Trips[Bus Type],"EV",Trips[Measured energy (kWh eq)],">0") -> 0 | E41: =SUMIFS(Trips[Modelled energy (kWh)],Trips[Bus Type],"Diesel",Trips[Measured energy (kWh eq)],">0") -> 0
A42: Calibration factor | D42: =IF(D40>0,D40/D41,1) -> 1 | E42: =IF(E40>0,E40/E41,1) -> 1
A46: Methodology
...

Sheet Trip_Input
A1: Trip inputs and energy calculations
A3: A:U come from 01_All_Pairs. V:Z are optional inputs. AA:BX are formulas. ICE is displayed as Diesel.
A4: Trip ID | B4: Pair ID | C4: Date | D4: Bus Type | E4: Corridor | F4: Direction | G4: Start Time | H4: t Charging (min) | I4: t Stop (min) | J4: t Idle (min) | K4: t Inching (min) | L4: t Acc (min) | M4: t Dec (min) | N4: t Cruise (min) | O4: d Charging (km) | P4: d Stop (km) | Q4: d Idle (km) | R4: d Inching (km) | S4: d Acc (km) | T4: d Dec (km) | U4: d Cruise (km) | V4: Passengers | W4: Ambient temp (C) | X4: Accel measured (m/s2) | Y4: Measured EV energy (kWh) | Z4: Measured diesel (L) | AA4: Data check | AB4: Month | AC4: Unique trip | AD4: Flag route | AE4: Flag period | AF4: Flag all | AG4: Net elevation (m) | AH4: Mass (kg) | AI4: Accel used (m/s2) | AJ4: Aux power (kW) | AK4: Distance (km) | AL4: Trip time incl charging (h) | AM4: Operating time (h) | AN4: Stationary time (h) | AO4: Moving time (h) | AP4: Moving speed (km/h) | AQ4: v Inching (km/h) | AR4: v Acc (km/h) | AS4: v Dec (km/h) | AT4: v Cruise (km/h) | AU4: Road-load traction (kWh) | AV4: Road-load Dec (kWh) | AW4: Inertial energy (kWh) | AX4: Grade energy (kWh) | AY4: Road-load net (kWh) | AZ4: Gradient wheel (kWh) | BA4: Braking energy (kWh) | BB4: Wheel energy (kWh) | BC4: Propulsion energy (kWh) | BD4: Auxiliary energy (kWh) | BE4: Idle fuel energy (kWh) | BF4: Regen recovered (kWh) | BG4: Modelled energy (kWh) | BH4: Measured energy (kWh eq) | BI4: Calibration factor | BJ4: Energy consumed (kWh) | BK4: Energy consumed (MJ) | BL4: Diesel consumed (L) | BM4: EV grid energy (kWh) | BN4: SEC (kWh/km) | BO4: Efficiency (km/kWh) | BP4: Fuel economy (km/L) | BQ4: Powertrain efficiency (%) | BR4: Energy cost (INR) | BS4: CO2 (kg) | BT4: Cost per km (INR/km) | BU4: CO2 per km (kg/km) | BV4: Model error vs measured | BW4: Chart SEC EV | BX4: Chart SEC Diesel
A5: PAIR_001_EV | B5: PAIR_001 | C5: 46208 | D5: EV | E5: Maduravoyal ↔ Silk Board | F5: Silk Board → Maduravoyal | G5: 0.35842593 | H5: 30 | I5: 23.65 | J5: 25.7 | K5: 7.6 | L5: 61.423733 | M5: 45.183333 | N5: 150.28333 | O5: 0.31331323 | P5: 0.041652319 | Q5: 0.15596841 | R5: 0.4492738 | S5: 60.308697 | T5: 44.619089 | U5: 199.27859 | AA5: =IF(AND(D5<>"EV",D5<>"Diesel"),"Invalid vehicle",IF(COUNTIFS(Routes[Corridor],E5,Routes[Direction],F5)=0,"Unknown route",IF(C5="","Missing date",IF(SUM(O5:U5)<=0,"No distance","OK")))) -> OK | AB5: =IF(C5="","",DATE(YEAR(C5),MONTH(C5),1)) -> 46204 | AC5: =--(COUNTIFS($C$5:C5,C5,$D$5:D5,D5,$G$5:G5,G5,$F$5:F5,F5)=1) -> 1 | AD5: =--AND(AA5="OK",OR(TAT_Sel_Basis="All pair instances",AC5=1),OR(TAT_Sel_Corridor="All",E5=TAT_Sel_Corridor),OR(TAT_Sel_DirEff="All",F5=TAT_Sel_DirEff)) -> 1 | AE5: =--AND(AA5="OK",OR(TAT_Sel_Basis="All pair instances",AC5=1),OR(TAT_Sel_Month="All",TEXT(AB5,"mmm yyyy")=TAT_Sel_Month)) -> 1 | AF5: =AD5*AE5 -> 1 | AG5: =SUMIFS(Routes[Net elevation (m)],Routes[Corridor],E5,Routes[Direction],F5) -> -885 | AH5: =IF(D5="EV",TAT_Kerb_EV,TAT_Kerb_D)+IF(V5="",TAT_Pax_Default,V5)*TAT_Pax_Mass -> 16500 | AI5: =IF(X5="",IF(D5="EV",TAT_Acc_EV,TAT_Acc_D),X5) -> 0.25 | AJ5: =IF(D5="EV",TAT_AuxBase_EV,TAT_AuxBase_D)+TAT_HVAC_k*MAX(0,IF(W5="",TAT_Temp_Default,W5)-TAT_HVAC_Tset) -> 8.1 | AK5: =SUM(O5:U5) -> 305.16659 | AL5: =SUM(H5:N5)/60 -> 5.7306733 | AM5: =SUM(I5:N5)/60 -> 5.2306733 | AN5: =SUM(I5:J5)/60 -> 0.8225 | AO5: =SUM(K5:N5)/60 -> 4.4081733 | AP5: =IFERROR(SUM(R5:U5)/AO5,0) -> 69.111541 | AQ5: =IFERROR(R5/(K5/60),0) -> 3.5468984 | AR5: =IFERROR(S5/(L5/60),0) -> 58.910808 | AS5: =IFERROR(T5/(M5/60),0) -> 59.250727 | AT5: =IFERROR(U5/(N5/60),0) -> 79.561155 | AU5: =(IF(D5="EV",TAT_Crr_EV,TAT_Crr_D)*AH5*TAT_G_acc*(AK5-T5)+IF(D5="EV",TAT_Kaero_EV,TAT_Kaero_D)*((AQ5/3.6)^2*R5+(AR5/3.6)^2*S5+(AT5/3.6)^2*U5))/3600 -> 181.1343 | AV5: =(IF(D5="EV",TAT_Crr_EV,TAT_Crr_D)*AH5*TAT_G_acc+IF(D5="EV",TAT_Kaero_EV,TAT_Kaero_D)*(AS5/3.6)^2)*T5/3600 -> 24.601255 | AW5: =AH5*AI5*S5/3600 -> 69.103715 | AX5: =AH5*TAT_G_acc*AG5/3600000 -> -39.791812 | AY5: =AU5+MAX(0,AV5-AW5) -> 181.1343 | AZ5: =MAX(0,AX5)-TAT_Descent_Share*MAX(0,-AX5) -> -19.895906 | BA5: =MAX(0,AW5-AV5)+(1-TAT_Descent_Share)*MAX(0,-AX5) -> 64.398366 | BB5: =MAX(0,AY5+AW5+AZ5) -> 230.34211 | BC5: =BB5/IF(D5="EV",TAT_EtaPT_EV,TAT_EtaPT_D) -> 277.73812 | BD5: =IF(D5="EV",AJ5*AM5,AJ5*AO5/TAT_EtaEng_D) -> 42.368454 | BE5: =IF(D5="EV",0,TAT_IdleFuel_D*AN5*TAT_LHV_kWhL) -> 0 | BF5: =IF(D5="EV",TAT_Regen_EV*TAT_EtaPT_EV*BA5,0) -> 32.045271 | BG5: =BC5+BD5+BE5-BF5 -> 288.06131 | BH5: =IF(D5="EV",IF(Y5="","",Y5),IF(Z5="","",Z5*TAT_LHV_kWhL)) | BI5: =IF(TAT_Cal_Apply="Yes",IF(D5="EV",TAT_CF_EV,TAT_CF_D),1) -> 1 | BJ5: =BG5*BI5 -> 288.06131 | BK5: =BJ5*3.6 -> 1037.0207 | BL5: =IF(D5="EV","",BJ5/TAT_LHV_kWhL) | BM5: =IF(D5="EV",BJ5/TAT_EtaCharger,"") -> 313.11012 | BN5: =IFERROR(BJ5/AK5,"") -> 0.94394773 | BO5: =IFERROR(AK5/BJ5,"") -> 1.0593807 | BP5: =IF(D5="EV","",IFERROR(AK5/BL5,"")) | BQ5: =IFERROR(BB5/BJ5,"") -> 0.79962879 | BR5: =IF(D5="EV",BM5*TAT_Tariff_EV,BL5*TAT_Price_Diesel) -> 2974.5461 | BS5: =IF(D5="EV",BM5*TAT_EF_Grid,BL5*TAT_EF_Diesel) -> 222.30818 | BT5: =IFERROR(BR5/AK5,"") -> 9.7472863 | BU5: =IFERROR(BS5/AK5,"") -> 0.7284814 | BV5: =IF(AND(ISNUMBER(BH5),BH5>0),BG5/BH5-1,"") | BW5: =IF(AND(AF5=1,D5="EV"),BN5,NA()) -> 0.94394773 | BX5: =IF(AND(AF5=1,D5="Diesel"),BN5,NA()) -> #N/A
A6: PAIR_001_ICE | B6: PAIR_001 | C6: 46232 | D6: Diesel | E6: Maduravoyal ↔ Silk Board | F6: Silk Board → Maduravoyal | G6: 0.95709491 | H6: 0 | I6: 18.1 | J6: 0.066666667 | K6: 1.75 | L6: 57.69085 | M6: 41.383333 | N6: 192.51667 | O6: 0 | P6: 0.2136487 | Q6: 0 | R6: 0.30731282 | S6: 55.580882 | T6: 38.886325 | U6: 215.48607 | AA6: =IF(AND(D6<>"EV",D6<>"Diesel"),"Invalid vehicle",IF(COUNTIFS(Routes[Corridor],E6,Routes[Direction],F6)=0,"Unknown route",IF(C6="","Missing date",IF(SUM(O6:U6)<=0,"No distance","OK")))) -> OK | AB6: =IF(C6="","",DATE(YEAR(C6),MONTH(C6),1)) -> 46204 | AC6: =--(COUNTIFS($C$5:C6,C6,$D$5:D6,D6,$G$5:G6,G6,$F$5:F6,F6)=1) -> 1 | AD6: =--AND(AA6="OK",OR(TAT_Sel_Basis="All pair instances",AC6=1),OR(TAT_Sel_Corridor="All",E6=TAT_Sel_Corridor),OR(TAT_Sel_DirEff="All",F6=TAT_Sel_DirEff)) -> 1 | AE6: =--AND(AA6="OK",OR(TAT_Sel_Basis="All pair instances",AC6=1),OR(TAT_Sel_Month="All",TEXT(AB6,"mmm yyyy")=TAT_Sel_Month)) -> 1 | AF6: =AD6*AE6 -> 1 | AG6: =SUMIFS(Routes[Net elevation (m)],Routes[Corridor],E6,Routes[Direction],F6) -> -885 | AH6: =IF(D6="EV",TAT_Kerb_EV,TAT_Kerb_D)+IF(V6="",TAT_Pax_Default,V6)*TAT_Pax_Mass -> 14500 | AI6: =IF(X6="",IF(D6="EV",TAT_Acc_EV,TAT_Acc_D),X6) -> 0.25 | AJ6: =IF(D6="EV",TAT_AuxBase_EV,TAT_AuxBase_D)+TAT_HVAC_k*MAX(0,IF(W6="",TAT_Temp_Default,W6)-TAT_HVAC_Tset) -> 8.1 | AK6: =SUM(O6:U6) -> 310.47424 | AL6: =SUM(H6:N6)/60 -> 5.1917919 | AM6: =SUM(I6:N6)/60 -> 5.1917919 | AN6: =SUM(I6:J6)/60 -> 0.30277778 | AO6: =SUM(K6:N6)/60 -> 4.8890142 | AP6: =IFERROR(SUM(R6:U6)/AO6,0) -> 63.460768 | AQ6: =IFERROR(R6/(K6/60),0) -> 10.53644 | AR6: =IFERROR(S6/(L6/60),0) -> 57.805578 | AS6: =IFERROR(T6/(M6/60),0) -> 56.37969 | AT6: =IFERROR(U6/(N6/60),0) -> 67.158676 | AU6: =(IF(D6="EV",TAT_Crr_EV,TAT_Crr_D)*AH6*TAT_G_acc*(AK6-T6)+IF(D6="EV",TAT_Kaero_EV,TAT_Kaero_D)*((AQ6/3.6)^2*R6+(AR6/3.6)^2*S6+(AT6/3.6)^2*U6))/3600 -> 153.1463 | AV6: =(IF(D6="EV",TAT_Crr_EV,TAT_Crr_D)*AH6*TAT_G_acc+IF(D6="EV",TAT_Kaero_EV,TAT_Kaero_D)*(AS6/3.6)^2)*T6/3600 -> 19.086795 | AW6: =AH6*AI6*S6/3600 -> 55.96686 | AX6: =AH6*TAT_G_acc*AG6/3600000 -> -34.968562 | AY6: =AU6+MAX(0,AV6-AW6) -> 153.1463 | AZ6: =MAX(0,AX6)-TAT_Descent_Share*MAX(0,-AX6) -> -17.484281 | BA6: =MAX(0,AW6-AV6)+(1-TAT_Descent_Share)*MAX(0,-AX6) -> 54.364346 | BB6: =MAX(0,AY6+AW6+AZ6) -> 191.62888 | BC6: =BB6/IF(D6="EV",TAT_EtaPT_EV,TAT_EtaPT_D) -> 595.12073 | BD6: =IF(D6="EV",AJ6*AM6,AJ6*AO6/TAT_EtaEng_D) -> 113.14576 | BE6: =IF(D6="EV",0,TAT_IdleFuel_D*AN6*TAT_LHV_kWhL) -> 7.5484182 | BF6: =IF(D6="EV",TAT_Regen_EV*TAT_EtaPT_EV*BA6,0) -> 0 | BG6: =BC6+BD6+BE6-BF6 -> 715.81491 | BH6: =IF(D6="EV",IF(Y6="","",Y6),IF(Z6="","",Z6*TAT_LHV_kWhL)) | BI6: =IF(TAT_Cal_Apply="Yes",IF(D6="EV",TAT_CF_EV,TAT_CF_D),1) -> 1 | BJ6: =BG6*BI6 -> 715.81491 | BK6: =BJ6*3.6 -> 2576.9337 | BL6: =IF(D6="EV","",BJ6/TAT_LHV_kWhL) -> 71.780882 | BM6: =IF(D6="EV",BJ6/TAT_EtaCharger,"") | BN6: =IFERROR(BJ6/AK6,"") -> 2.3055533 | BO6: =IFERROR(AK6/BJ6,"") -> 0.43373537 | BP6: =IF(D6="EV","",IFERROR(AK6/BL6,"")) -> 4.3253055 | BQ6: =IFERROR(BB6/BJ6,"") -> 0.2677073 | BR6: =IF(D6="EV",BM6*TAT_Tariff_EV,BL6*TAT_Price_Diesel) -> 6603.8411 | BS6: =IF(D6="EV",BM6*TAT_EF_Grid,BL6*TAT_EF_Diesel) -> 192.37276 | BT6: =IFERROR(BR6/AK6,"") -> 21.270174 | BU6: =IFERROR(BS6/AK6,"") -> 0.61960942 | BV6: =IF(AND(ISNUMBER(BH6),BH6>0),BG6/BH6-1,"") | BW6: =IF(AND(AF6=1,D6="EV"),BN6,NA()) -> #N/A | BX6: =IF(AND(AF6=1,D6="Diesel"),BN6,NA()) -> 2.3055533
A7: PAIR_002_EV | B7: PAIR_002 | C7: 46208 | D7: EV | E7: Maduravoyal ↔ Silk Board | F7: Silk Board → Maduravoyal | G7: 0.35842593 | H7: 30 | I7: 23.65 | J7: 25.7 | K7: 7.6 | L7: 61.423733 | M7: 45.183333 | N7: 150.28333 | O7: 0.31331323 | P7: 0.041652319 | Q7: 0.15596841 | R7: 0.4492738 | S7: 60.301496 | T7: 44.619089 | U7: 199.22648 | AA7: =IF(AND(D7<>"EV",D7<>"Diesel"),"Invalid vehicle",IF(COUNTIFS(Routes[Corridor],E7,Routes[Direction],F7)=0,"Unknown route",IF(C7="","Missing date",IF(SUM(O7:U7)<=0,"No distance","OK")))) -> OK | AB7: =IF(C7="","",DATE(YEAR(C7),MONTH(C7),1)) -> 46204 | AC7: =--(COUNTIFS($C$5:C7,C7,$D$5:D7,D7,$G$5:G7,G7,$F$5:F7,F7)=1) -> 0 | AD7: =--AND(AA7="OK",OR(TAT_Sel_Basis="All pair instances",AC7=1),OR(TAT_Sel_Corridor="All",E7=TAT_Sel_Corridor),OR(TAT_Sel_DirEff="All",F7=TAT_Sel_DirEff)) -> 1 | AE7: =--AND(AA7="OK",OR(TAT_Sel_Basis="All pair instances",AC7=1),OR(TAT_Sel_Month="All",TEXT(AB7,"mmm yyyy")=TAT_Sel_Month)) -> 1 | AF7: =AD7*AE7 -> 1 | AG7: =SUMIFS(Routes[Net elevation (m)],Routes[Corridor],E7,Routes[Direction],F7) -> -885 | AH7: =IF(D7="EV",TAT_Kerb_EV,TAT_Kerb_D)+IF(V7="",TAT_Pax_Default,V7)*TAT_Pax_Mass -> 16500 | AI7: =IF(X7="",IF(D7="EV",TAT_Acc_EV,TAT_Acc_D),X7) -> 0.25 | AJ7: =IF(D7="EV",TAT_AuxBase_EV,TAT_AuxBase_D)+TAT_HVAC_k*MAX(0,IF(W7="",TAT_Temp_Default,W7)-TAT_HVAC_Tset) -> 8.1 | AK7: =SUM(O7:U7) -> 305.10728 | AL7: =SUM(H7:N7)/60 -> 5.7306733 | AM7: =SUM(I7:N7)/60 -> 5.2306733 | AN7: =SUM(I7:J7)/60 -> 0.8225 | AO7: =SUM(K7:N7)/60 -> 4.4081733 | AP7: =IFERROR(SUM(R7:U7)/AO7,0) -> 69.098087 | AQ7: =IFERROR(R7/(K7/60),0) -> 3.5468984 | AR7: =IFERROR(S7/(L7/60),0) -> 58.903775 | AS7: =IFERROR(T7/(M7/60),0) -> 59.250727 | AT7: =IFERROR(U7/(N7/60),0) -> 79.540351 | AU7: =(IF(D7="EV",TAT_Crr_EV,TAT_Crr_D)*AH7*TAT_G_acc*(AK7-T7)+IF(D7="EV",TAT_Kaero_EV,TAT_Kaero_D)*((AQ7/3.6)^2*R7+(AR7/3.6)^2*S7+(AT7/3.6)^2*U7))/3600 -> 181.0439 | AV7: =(IF(D7="EV",TAT_Crr_EV,TAT_Crr_D)*AH7*TAT_G_acc+IF(D7="EV",TAT_Kaero_EV,TAT_Kaero_D)*(AS7/3.6)^2)*T7/3600 -> 24.601255 | AW7: =AH7*AI7*S7/3600 -> 69.095465 | AX7: =AH7*TAT_G_acc*AG7/3600000 -> -39.791812 | AY7: =AU7+MAX(0,AV7-AW7) -> 181.0439 | AZ7: =MAX(0,AX7)-TAT_Descent_Share*MAX(0,-AX7) -> -19.895906 | BA7: =MAX(0,AW7-AV7)+(1-TAT_Descent_Share)*MAX(0,-AX7) -> 64.390116 | BB7: =MAX(0,AY7+AW7+AZ7) -> 230.24346 | BC7: =BB7/IF(D7="EV",TAT_EtaPT_EV,TAT_EtaPT_D) -> 277.61918 | BD7: =IF(D7="EV",AJ7*AM7,AJ7*AO7/TAT_EtaEng_D) -> 42.368454 | BE7: =IF(D7="EV",0,TAT_IdleFuel_D*AN7*TAT_LHV_kWhL) -> 0 | BF7: =IF(D7="EV",TAT_Regen_EV*TAT_EtaPT_EV*BA7,0) -> 32.041165 | BG7: =BC7+BD7+BE7-BF7 -> 287.94646 | BH7: =IF(D7="EV",IF(Y7="","",Y7),IF(Z7="","",Z7*TAT_LHV_kWhL)) | BI7: =IF(TAT_Cal_Apply="Yes",IF(D7="EV",TAT_CF_EV,TAT_CF_D),1) -> 1 | BJ7: =BG7*BI7 -> 287.94646 | BK7: =BJ7*3.6 -> 1036.6073 | BL7: =IF(D7="EV","",BJ7/TAT_LHV_kWhL) | BM7: =IF(D7="EV",BJ7/TAT_EtaCharger,"") -> 312.98529 | BN7: =IFERROR(BJ7/AK7,"") -> 0.94375482 | BO7: =IFERROR(AK7/BJ7,"") -> 1.0595972 | BP7: =IF(D7="EV","",IFERROR(AK7/BL7,"")) | BQ7: =IFERROR(BB7/BJ7,"") -> 0.79960511 | BR7: =IF(D7="EV",BM7*TAT_Tariff_EV,BL7*TAT_Price_Diesel) -> 2973.3602 | BS7: =IF(D7="EV",BM7*TAT_EF_Grid,BL7*TAT_EF_Diesel) -> 222.21955 | BT7: =IFERROR(BR7/AK7,"") -> 9.7452943 | BU7: =IFERROR(BS7/AK7,"") -> 0.72833252 | BV7: =IF(AND(ISNUMBER(BH7),BH7>0),BG7/BH7-1,"") | BW7: =IF(AND(AF7=1,D7="EV"),BN7,NA()) -> 0.94375482 | BX7: =IF(AND(AF7=1,D7="Diesel"),BN7,NA()) -> #N/A
A8: PAIR_002_ICE | B8: PAIR_002 | C8: 46270 | D8: Diesel | E8: Maduravoyal ↔ Silk Board | F8: Silk Board → Maduravoyal | G8: 0.96938657 | H8: 0 | I8: 16.433333 | J8: 6.9833333 | K8: 5 | L8: 60.018217 | M8: 42.633333 | N8: 167.95 | O8: 0 | P8: 0.083882197 | Q8: 0.03091496 | R8: 0.23093108 | S8: 57.928894 | T8: 43.162925 | U8: 203.77853 | AA8: =IF(AND(D8<>"EV",D8<>"Diesel"),"Invalid vehicle",IF(COUNTIFS(Routes[Corridor],E8,Routes[Direction],F8)=0,"Unknown route",IF(C8="","Missing date",IF(SUM(O8:U8)<=0,"No distance","OK")))) -> OK | AB8: =IF(C8="","",DATE(YEAR(C8),MONTH(C8),1)) -> 46266 | AC8: =--(COUNTIFS($C$5:C8,C8,$D$5:D8,D8,$G$5:G8,G8,$F$5:F8,F8)=1) -> 1 | AD8: =--AND(AA8="OK",OR(TAT_Sel_Basis="All pair instances",AC8=1),OR(TAT_Sel_Corridor="All",E8=TAT_Sel_Corridor),OR(TAT_Sel_DirEff="All",F8=TAT_Sel_DirEff)) -> 1 | AE8: =--AND(AA8="OK",OR(TAT_Sel_Basis="All pair instances",AC8=1),OR(TAT_Sel_Month="All",TEXT(AB8,"mmm yyyy")=TAT_Sel_Month)) -> 1 | AF8: =AD8*AE8 -> 1 | AG8: =SUMIFS(Routes[Net elevation (m)],Routes[Corridor],E8,Routes[Direction],F8) -> -885 | AH8: =IF(D8="EV",TAT_Kerb_EV,TAT_Kerb_D)+IF(V8="",TAT_Pax_Default,V8)*TAT_Pax_Mass -> 14500 | AI8: =IF(X8="",IF(D8="EV",TAT_Acc_EV,TAT_Acc_D),X8) -> 0.25 | AJ8: =IF(D8="EV",TAT_AuxBase_EV,TAT_AuxBase_D)+TAT_HVAC_k*MAX(0,IF(W8="",TAT_Temp_Default,W8)-TAT_HVAC_Tset) -> 8.1 | AK8: =SUM(O8:U8) -> 305.21608 | AL8: =SUM(H8:N8)/60 -> 4.9836369 | AM8: =SUM(I8:N8)/60 -> 4.9836369 | AN8: =SUM(I8:J8)/60 -> 0.39027778 | AO8: =SUM(K8:N8)/60 -> 4.5933592 | AP8: =IFERROR(SUM(R8:U8)/AO8,0) -> 66.422256 | AQ8: =IFERROR(R8/(K8/60),0) -> 2.771173 | AR8: =IFERROR(S8/(L8/60),0) -> 57.911311 | AS8: =IFERROR(T8/(M8/60),0) -> 60.745321 | AT8: =IFERROR(U8/(N8/60),0) -> 72.799712 | AU8: =(IF(D8="EV",TAT_Crr_EV,TAT_Crr_D)*AH8*TAT_G_acc*(AK8-T8)+IF(D8="EV",TAT_Kaero_EV,TAT_Kaero_D)*((AQ8/3.6)^2*R8+(AR8/3.6)^2*S8+(AT8/3.6)^2*U8))/3600 -> 158.36837 | AV8: =(IF(D8="EV",TAT_Crr_EV,TAT_Crr_D)*AH8*TAT_G_acc+IF(D8="EV",TAT_Kaero_EV,TAT_Kaero_D)*(AS8/3.6)^2)*T8/3600 -> 22.673479 | AW8: =AH8*AI8*S8/3600 -> 58.331178 | AX8: =AH8*TAT_G_acc*AG8/3600000 -> -34.968562 | AY8: =AU8+MAX(0,AV8-AW8) -> 158.36837 | AZ8: =MAX(0,AX8)-TAT_Descent_Share*MAX(0,-AX8) -> -17.484281 | BA8: =MAX(0,AW8-AV8)+(1-TAT_Descent_Share)*MAX(0,-AX8) -> 53.14198 | BB8: =MAX(0,AY8+AW8+AZ8) -> 199.21526 | BC8: =BB8/IF(D8="EV",TAT_EtaPT_EV,TAT_EtaPT_D) -> 618.68094 | BD8: =IF(D8="EV",AJ8*AM8,AJ8*AO8/TAT_EtaEng_D) -> 106.30346 | BE8: =IF(D8="EV",0,TAT_IdleFuel_D*AN8*TAT_LHV_kWhL) -> 9.7298418 | BF8: =IF(D8="EV",TAT_Regen_EV*TAT_EtaPT_EV*BA8,0) -> 0 | BG8: =BC8+BD8+BE8-BF8 -> 734.71423 | BH8: =IF(D8="EV",IF(Y8="","",Y8),IF(Z8="","",Z8*TAT_LHV_kWhL)) | BI8: =IF(TAT_Cal_Apply="Yes",IF(D8="EV",TAT_CF_EV,TAT_CF_D),1) -> 1 | BJ8: =BG8*BI8 -> 734.71423 | BK8: =BJ8*3.6 -> 2644.9712 | BL8: =IF(D8="EV","",BJ8/TAT_LHV_kWhL) -> 73.676079 | BM8: =IF(D8="EV",BJ8/TAT_EtaCharger,"") | BN8: =IFERROR(BJ8/AK8,"") -> 2.4071938 | BO8: =IFERROR(AK8/BJ8,"") -> 0.41542148 | BP8: =IF(D8="EV","",IFERROR(AK8/BL8,"")) -> 4.1426753 | BQ8: =IFERROR(BB8/BJ8,"") -> 0.27114659 | BR8: =IF(D8="EV",BM8*TAT_Tariff_EV,BL8*TAT_Price_Diesel) -> 6778.1993 | BS8: =IF(D8="EV",BM8*TAT_EF_Grid,BL8*TAT_EF_Diesel) -> 197.45189 | BT8: =IFERROR(BR8/AK8,"") -> 22.207871 | BU8: =IFERROR(BS8/AK8,"") -> 0.64692494 | BV8: =IF(AND(ISNUMBER(BH8),BH8>0),BG8/BH8-1,"") | BW8: =IF(AND(AF8=1,D8="EV"),BN8,NA()) -> #N/A | BX8: =IF(AND(AF8=1,D8="Diesel"),BN8,NA()) -> 2.4071938
A9: PAIR_003_EV | B9: PAIR_003 | C9: 46213 | D9: EV | E9: Maduravoyal ↔ Silk Board | F9: Maduravoyal → Silk Board | G9: 0.016851852 | H9: 38.333333 | I9: 10.566667 | J9: 0 | K9: 0.66666667 | L9: 49.316667 | M9: 44.583333 | N9: 202.15 | O9: 0.3220724 | P9: 0.46962669 | Q9: 0 | R9: 0.2646788 | S9: 46.828639 | T9: 41.95381 | U9: 230.50068 | AA9: =IF(AND(D9<>"EV",D9<>"Diesel"),"Invalid vehicle",IF(COUNTIFS(Routes[Corridor],E9,Routes[Direction],F9)=0,"Unknown route",IF(C9="","Missing date",IF(SUM(O9:U9)<=0,"No distance","OK")))) -> OK | AB9: =IF(C9="","",DATE(YEAR(C9),MONTH(C9),1)) -> 46204 | AC9: =--(COUNTIFS($C$5:C9,C9,$D$5:D9,D9,$G$5:G9,G9,$F$5:F9,F9)=1) -> 1 | AD9: =--AND(AA9="OK",OR(TAT_Sel_Basis="All pair instances",AC9=1),OR(TAT_Sel_Corridor="All",E9=TAT_Sel_Corridor),OR(TAT_Sel_DirEff="All",F9=TAT_Sel_DirEff)) -> 1 | AE9: =--AND(AA9="OK",OR(TAT_Sel_Basis="All pair instances",AC9=1),OR(TAT_Sel_Month="All",TEXT(AB9,"mmm yyyy")=TAT_Sel_Month)) -> 1 | AF9: =AD9*AE9 -> 1 | AG9: =SUMIFS(Routes[Net elevation (m)],Routes[Corridor],E9,Routes[Direction],F9) -> 885 | AH9: =IF(D9="EV",TAT_Kerb_EV,TAT_Kerb_D)+IF(V9="",TAT_Pax_Default,V9)*TAT_Pax_Mass -> 16500 | AI9: =IF(X9="",IF(D9="EV",TAT_Acc_EV,TAT_Acc_D),X9) -> 0.25 | AJ9: =IF(D9="EV",TAT_AuxBase_EV,TAT_AuxBase_D)+TAT_HVAC_k*MAX(0,IF(W9="",TAT_Temp_Default,W9)-TAT_HVAC_Tset) -> 8.1 | AK9: =SUM(O9:U9) -> 320.33951 | AL9: =SUM(H9:N9)/60 -> 5.7602778 | AM9: =SUM(I9:N9)/60 -> 5.1213889 | AN9: =SUM(I9:J9)/60 -> 0.17611111 | AO9: =SUM(K9:N9)/60 -> 4.9452778 | AP9: =IFERROR(SUM(R9:U9)/AO9,0) -> 64.616757 | AQ9: =IFERROR(R9/(K9/60),0) -> 23.821092 | AR9: =IFERROR(S9/(L9/60),0) -> 56.972998 | AS9: =IFERROR(T9/(M9/60),0) -> 56.461202 | AT9: =IFERROR(U9/(N9/60),0) -> 68.414746 | AU9: =(IF(D9="EV",TAT_Crr_EV,TAT_Crr_D)*AH9*TAT_G_acc*(AK9-T9)+IF(D9="EV",TAT_Kaero_EV,TAT_Kaero_D)*((AQ9/3.6)^2*R9+(AR9/3.6)^2*S9+(AT9/3.6)^2*U9))/3600 -> 170.59201 | AV9: =(IF(D9="EV",TAT_Crr_EV,TAT_Crr_D)*AH9*TAT_G_acc+IF(D9="EV",TAT_Kaero_EV,TAT_Kaero_D)*(AS9/3.6)^2)*T9/3600 -> 22.218973 | AW9: =AH9*AI9*S9/3600 -> 53.657816 | AX9: =AH9*TAT_G_acc*AG9/3600000 -> 39.791812 | AY9: =AU9+MAX(0,AV9-AW9) -> 170.59201 | AZ9: =MAX(0,AX9)-TAT_Descent_Share*MAX(0,-AX9) -> 39.791812 | BA9: =MAX(0,AW9-AV9)+(1-TAT_Descent_Share)*MAX(0,-AX9) -> 31.438843 | BB9: =MAX(0,AY9+AW9+AZ9) -> 264.04164 | BC9: =BB9/IF(D9="EV",TAT_EtaPT_EV,TAT_EtaPT_D) -> 318.37178 | BD9: =IF(D9="EV",AJ9*AM9,AJ9*AO9/TAT_EtaEng_D) -> 41.48325 | BE9: =IF(D9="EV",0,TAT_IdleFuel_D*AN9*TAT_LHV_kWhL) -> 0 | BF9: =IF(D9="EV",TAT_Regen_EV*TAT_EtaPT_EV*BA9,0) -> 15.644283 | BG9: =BC9+BD9+BE9-BF9 -> 344.21075 | BH9: =IF(D9="EV",IF(Y9="","",Y9),IF(Z9="","",Z9*TAT_LHV_kWhL)) | BI9: =IF(TAT_Cal_Apply="Yes",IF(D9="EV",TAT_CF_EV,TAT_CF_D),1) -> 1 | BJ9: =BG9*BI9 -> 344.21075 | BK9: =BJ9*3.6 -> 1239.1587 | BL9: =IF(D9="EV","",BJ9/TAT_LHV_kWhL) | BM9: =IF(D9="EV",BJ9/TAT_EtaCharger,"") -> 374.14212 | BN9: =IFERROR(BJ9/AK9,"") -> 1.0745186 | BO9: =IFERROR(AK9/BJ9,"") -> 0.93064935 | BP9: =IF(D9="EV","",IFERROR(AK9/BL9,"")) | BQ9: =IFERROR(BB9/BJ9,"") -> 0.76709294 | BR9: =IF(D9="EV",BM9*TAT_Tariff_EV,BL9*TAT_Price_Diesel) -> 3554.3501 | BS9: =IF(D9="EV",BM9*TAT_EF_Grid,BL9*TAT_EF_Diesel) -> 265.6409 | BT9: =IFERROR(BR9/AK9,"") -> 11.095572 | BU9: =IFERROR(BS9/AK9,"") -> 0.82924802 | BV9: =IF(AND(ISNUMBER(BH9),BH9>0),BG9/BH9-1,"") | BW9: =IF(AND(AF9=1,D9="EV"),BN9,NA()) -> 1.0745186 | BX9: =IF(AND(AF9=1,D9="Diesel"),BN9,NA()) -> #N/A
A10: PAIR_003_ICE | B10: PAIR_003 | C10: 46234 | D10: Diesel | E10: Maduravoyal ↔ Silk Board | F10: Maduravoyal → Silk Board | G10: 0.97584491 | H10: 0 | I10: 35.983333 | J10: 0.35 | K10: 4.0833333 | L10: 62.08705 | M10: 50.533333 | N10: 205.36038 | O10: 0 | P10: 0.34734042 | Q10: 0 | R10: 0.4374014 | S10: 58.410381 | T10: 47.464359 | U10: 214.02954 | AA10: =IF(AND(D10<>"EV",D10<>"Diesel"),"Invalid vehicle",IF(COUNTIFS(Routes[Corridor],E10,Routes[Direction],F10)=0,"Unknown route",IF(C10="","Missing date",IF(SUM(O10:U10)<=0,"No distance","OK")))) -> OK | AB10: =IF(C10="","",DATE(YEAR(C10),MONTH(C10),1)) -> 46204 | AC10: =--(COUNTIFS($C$5:C10,C10,$D$5:D10,D10,$G$5:G10,G10,$F$5:F10,F10)=1) -> 1 | AD10: =--AND(AA10="OK",OR(TAT_Sel_Basis="All pair instances",AC10=1),OR(TAT_Sel_Corridor="All",E10=TAT_Sel_Corridor),OR(TAT_Sel_DirEff="All",F10=TAT_Sel_DirEff)) -> 1 | AE10: =--AND(AA10="OK",OR(TAT_Sel_Basis="All pair instances",AC10=1),OR(TAT_Sel_Month="All",TEXT(AB10,"mmm yyyy")=TAT_Sel_Month)) -> 1 | AF10: =AD10*AE10 -> 1 | AG10: =SUMIFS(Routes[Net elevation (m)],Routes[Corridor],E10,Routes[Direction],F10) -> 885 | AH10: =IF(D10="EV",TAT_Kerb_EV,TAT_Kerb_D)+IF(V10="",TAT_Pax_Default,V10)*TAT_Pax_Mass -> 14500 | AI10: =IF(X10="",IF(D10="EV",TAT_Acc_EV,TAT_Acc_D),X10) -> 0.25 | AJ10: =IF(D10="EV",TAT_AuxBase_EV,TAT_AuxBase_D)+TAT_HVAC_k*MAX(0,IF(W10="",TAT_Temp_Default,W10)-TAT_HVAC_Tset) -> 8.1 | AK10: =SUM(O10:U10) -> 320.68902 | AL10: =SUM(H10:N10)/60 -> 5.9732906 | AM10: =SUM(I10:N10)/60 -> 5.9732906 | AN10: =SUM(I10:J10)/60 -> 0.60555556 | AO10: =SUM(K10:N10)/60 -> 5.367735 | AP10: =IFERROR(SUM(R10:U10)/AO10,0) -> 59.679116 | AQ10: =IFERROR(R10/(K10/60),0) -> 6.4271227 | AR10: =IFERROR(S10/(L10/60),0) -> 56.446922 | AS10: =IFERROR(T10/(M10/60),0) -> 56.3561 | AT10: =IFERROR(U10/(N10/60),0) -> 62.53286 | AU10: =(IF(D10="EV",TAT_Crr_EV,TAT_Crr_D)*AH10*TAT_G_acc*(AK10-T10)+IF(D10="EV",TAT_Kaero_EV,TAT_Kaero_D)*((AQ10/3.6)^2*R10+(AR10/3.6)^2*S10+(AT10/3.6)^2*U10))/3600 -> 144.52669 | AV10: =(IF(D10="EV",TAT_Crr_EV,TAT_Crr_D)*AH10*TAT_G_acc+IF(D10="EV",TAT_Kaero_EV,TAT_Kaero_D)*(AS10/3.6)^2)*T10/3600 -> 23.288692 | AW10: =AH10*AI10*S10/3600 -> 58.816009 | AX10: =AH10*TAT_G_acc*AG10/3600000 -> 34.968562 | AY10: =AU10+MAX(0,AV10-AW10) -> 144.52669 | AZ10: =MAX(0,AX10)-TAT_Descent_Share*MAX(0,-AX10) -> 34.968562 | BA10: =MAX(0,AW10-AV10)+(1-TAT_Descent_Share)*MAX(0,-AX10) -> 35.527317 | BB10: =MAX(0,AY10+AW10+AZ10) -> 238.31126 | BC10: =BB10/IF(D10="EV",TAT_EtaPT_EV,TAT_EtaPT_D) -> 740.09709 | BD10: =IF(D10="EV",AJ10*AM10,AJ10*AO10/TAT_EtaEng_D) -> 124.22472 | BE10: =IF(D10="EV",0,TAT_IdleFuel_D*AN10*TAT_LHV_kWhL) -> 15.096836 | BF10: =IF(D10="EV",TAT_Regen_EV*TAT_EtaPT_EV*BA10,0) -> 0 | BG10: =BC10+BD10+BE10-BF10 -> 879.41865 | BH10: =IF(D10="EV",IF(Y10="","",Y10),IF(Z10="","",Z10*TAT_LHV_kWhL)) | BI10: =IF(TAT_Cal_Apply="Yes",IF(D10="EV",TAT_CF_EV,TAT_CF_D),1) -> 1 | BJ10: =BG10*BI10 -> 879.41865 | BK10: =BJ10*3.6 -> 3165.9071 | BL10: =IF(D10="EV","",BJ10/TAT_LHV_kWhL) -> 88.186829 | BM10: =IF(D10="EV",BJ10/TAT_EtaCharger,"") | BN10: =IFERROR(BJ10/AK10,"") -> 2.7422787 | BO10: =IFERROR(AK10/BJ10,"") -> 0.36466024 | BP10: =IF(D10="EV","",IFERROR(AK10/BL10,"")) -> 3.636473 | BQ10: =IFERROR(BB10/BJ10,"") -> 0.27098727 | BR10: =IF(D10="EV",BM10*TAT_Tariff_EV,BL10*TAT_Price_Diesel) -> 8113.1882 | BS10: =IF(D10="EV",BM10*TAT_EF_Grid,BL10*TAT_EF_Diesel) -> 236.3407 | BT10: =IFERROR(BR10/AK10,"") -> 25.299239 | BU10: =IFERROR(BS10/AK10,"") -> 0.73697784 | BV10: =IF(AND(ISNUMBER(BH10),BH10>0),BG10/BH10-1,"") | BW10: =IF(AND(AF10=1,D10="EV"),BN10,NA()) -> #N/A | BX10: =IF(AND(AF10=1,D10="Diesel"),BN10,NA()) -> 2.7422787
A11: PAIR_004_EV | B11: PAIR_004 | C11: 46218 | D11: EV | E11: Chennai ↔ Pondicherry | F11: Chennai → Pondicherry | G11: 0.39075231 | H11: 0 | I11: 25.883333 | J11: 8.15 | K11: 8.0166667 | L11: 55.883333 | M11: 40.116667 | N11: 102.39363 | O11: 0 | P11: 0.35568686 | Q11: 0.57585003 | R11: 0.6265752 | S11: 44.777395 | T11: 31.03077 | U11: 70.832492 | AA11: =IF(AND(D11<>"EV",D11<>"Diesel"),"Invalid vehicle",IF(COUNTIFS(Routes[Corridor],E11,Routes[Direction],F11)=0,"Unknown route",IF(C11="","Missing date",IF(SUM(O11:U11)<=0,"No distance","OK")))) -> OK | AB11: =IF(C11="","",DATE(YEAR(C11),MONTH(C11),1)) -> 46204 | AC11: =--(COUNTIFS($C$5:C11,C11,$D$5:D11,D11,$G$5:G11,G11,$F$5:F11,F11)=1) -> 1 | AD11: =--AND(AA11="OK",OR(TAT_Sel_Basis="All pair instances",AC11=1),OR(TAT_Sel_Corridor="All",E11=TAT_Sel_Corridor),OR(TAT_Sel_DirEff="All",F11=TAT_Sel_DirEff)) -> 0 | AE11: =--AND(AA11="OK",OR(TAT_Sel_Basis="All pair instances",AC11=1),OR(TAT_Sel_Month="All",TEXT(AB11,"mmm yyyy")=TAT_Sel_Month)) -> 1 | AF11: =AD11*AE11 -> 0 | AG11: =SUMIFS(Routes[Net elevation (m)],Routes[Corridor],E11,Routes[Direction],F11) -> -5 | AH11: =IF(D11="EV",TAT_Kerb_EV,TAT_Kerb_D)+IF(V11="",TAT_Pax_Default,V11)*TAT_Pax_Mass -> 16500 | AI11: =IF(X11="",IF(D11="EV",TAT_Acc_EV,TAT_Acc_D),X11) -> 0.25 | AJ11: =IF(D11="EV",TAT_AuxBase_EV,TAT_AuxBase_D)+TAT_HVAC_k*MAX(0,IF(W11="",TAT_Temp_Default,W11)-TAT_HVAC_Tset) -> 8.1 | AK11: =SUM(O11:U11) -> 148.19877 | AL11: =SUM(H11:N11)/60 -> 4.0073939 | AM11: =SUM(I11:N11)/60 -> 4.0073939 | AN11: =SUM(I11:J11)/60 -> 0.56722222 | AO11: =SUM(K11:N11)/60 -> 3.4401717 | AP11: =IFERROR(SUM(R11:U11)/AO11,0) -> 42.808106 | AQ11: =IFERROR(R11/(K11/60),0) -> 4.6895441 | AR11: =IFERROR(S11/(L11/60),0) -> 48.075938 | AS11: =IFERROR(T11/(M11/60),0) -> 46.41079 | AT11: =IFERROR(U11/(N11/60),0) -> 41.505994 | AU11: =(IF(D11="EV",TAT_Crr_EV,TAT_Crr_D)*AH11*TAT_G_acc*(AK11-T11)+IF(D11="EV",TAT_Kaero_EV,TAT_Kaero_D)*((AQ11/3.6)^2*R11+(AR11/3.6)^2*S11+(AT11/3.6)^2*U11))/3600 -> 52.078574 | AV11: =(IF(D11="EV",TAT_Crr_EV,TAT_Crr_D)*AH11*TAT_G_acc+IF(D11="EV",TAT_Kaero_EV,TAT_Kaero_D)*(AS11/3.6)^2)*T11/3600 -> 14.271624 | AW11: =AH11*AI11*S11/3600 -> 51.307431 | AX11: =AH11*TAT_G_acc*AG11/3600000 -> -0.2248125 | AY11: =AU11+MAX(0,AV11-AW11) -> 52.078574 | AZ11: =MAX(0,AX11)-TAT_Descent_Share*MAX(0,-AX11) -> -0.11240625 | BA11: =MAX(0,AW11-AV11)+(1-TAT_Descent_Share)*MAX(0,-AX11) -> 37.148214 | BB11: =MAX(0,AY11+AW11+AZ11) -> 103.2736 | BC11: =BB11/IF(D11="EV",TAT_EtaPT_EV,TAT_EtaPT_D) -> 124.52354 | BD11: =IF(D11="EV",AJ11*AM11,AJ11*AO11/TAT_EtaEng_D) -> 32.45989 | BE11: =IF(D11="EV",0,TAT_IdleFuel_D*AN11*TAT_LHV_kWhL) -> 0 | BF11: =IF(D11="EV",TAT_Regen_EV*TAT_EtaPT_EV*BA11,0) -> 18.485323 | BG11: =BC11+BD11+BE11-BF11 -> 138.49811 | BH11: =IF(D11="EV",IF(Y11="","",Y11),IF(Z11="","",Z11*TAT_LHV_kWhL)) | BI11: =IF(TAT_Cal_Apply="Yes",IF(D11="EV",TAT_CF_EV,TAT_CF_D),1) -> 1 | BJ11: =BG11*BI11 -> 138.49811 | BK11: =BJ11*3.6 -> 498.59319 | BL11: =IF(D11="EV","",BJ11/TAT_LHV_kWhL) | BM11: =IF(D11="EV",BJ11/TAT_EtaCharger,"") -> 150.54142 | BN11: =IFERROR(BJ11/AK11,"") -> 0.93454291 | BO11: =IFERROR(AK11/BJ11,"") -> 1.0700418 | BP11: =IF(D11="EV","",IFERROR(AK11/BL11,"")) | BQ11: =IFERROR(BB11/BJ11,"") -> 0.74566793 | BR11: =IF(D11="EV",BM11*TAT_Tariff_EV,BL11*TAT_Price_Diesel) -> 1430.1435 | BS11: =IF(D11="EV",BM11*TAT_EF_Grid,BL11*TAT_EF_Diesel) -> 106.88441 | BT11: =IFERROR(BR11/AK11,"") -> 9.6501714 | BU11: =IFERROR(BS11/AK11,"") -> 0.72122334 | BV11: =IF(AND(ISNUMBER(BH11),BH11>0),BG11/BH11-1,"") | BW11: =IF(AND(AF11=1,D11="EV"),BN11,NA()) -> #N/A | BX11: =IF(AND(AF11=1,D11="Diesel"),BN11,NA()) -> #N/A
A12: PAIR_004_ICE | B12: PAIR_004 | C12: 46218 | D12: Diesel | E12: Chennai ↔ Pondicherry | F12: Chennai → Pondicherry | G12: 0.47248843 | H12: 0 | I12: 69.483333 | J12: 9.95 | K12: 1.7166667 | L12: 25.133333 | M12: 23.433333 | N12: 144.63333 | O12: 0 | P12: 0.83987814 | Q12: 1.7979996 | R12: 0.57590785 | S12: 16.043683 | T12: 16.779597 | U12: 112.08835 | AA12: =IF(AND(D12<>"EV",D12<>"Diesel"),"Invalid vehicle",IF(COUNTIFS(Routes[Corridor],E12,Routes[Direction],F12)=0,"Unknown route",IF(C12="","Missing date",IF(SUM(O12:U12)<=0,"No distance","OK")))) -> OK | AB12: =IF(C12="","",DATE(YEAR(C12),MONTH(C12),1)) -> 46204 | AC12: =--(COUNTIFS($C$5:C12,C12,$D$5:D12,D12,$G$5:G12,G12,$F$5:F12,F12)=1) -> 1 | AD12: =--AND(AA12="OK",OR(TAT_Sel_Basis="All pair instances",AC12=1),OR(TAT_Sel_Corridor="All",E12=TAT_Sel_Corridor),OR(TAT_Sel_DirEff="All",F12=TAT_Sel_DirEff)) -> 0 | AE12: =--AND(AA12="OK",OR(TAT_Sel_Basis="All pair instances",AC12=1),OR(TAT_Sel_Month="All",TEXT(AB12,"mmm yyyy")=TAT_Sel_Month)) -> 1 | AF12: =AD12*AE12 -> 0 | AG12: =SUMIFS(Routes[Net elevation (m)],Routes[Corridor],E12,Routes[Direction],F12) -> -5 | AH12: =IF(D12="EV",TAT_Kerb_EV,TAT_Kerb_D)+IF(V12="",TAT_Pax_Default,V12)*TAT_Pax_Mass -> 14500 | AI12: =IF(X12="",IF(D12="EV",TAT_Acc_EV,TAT_Acc_D),X12) -> 0.25 | AJ12: =IF(D12="EV",TAT_AuxBase_EV,TAT_AuxBase_D)+TAT_HVAC_k*MAX(0,IF(W12="",TAT_Temp_Default,W12)-TAT_HVAC_Tset) -> 8.1 | AK12: =SUM(O12:U12) -> 148.12542 | AL12: =SUM(H12:N12)/60 -> 4.5725 | AM12: =SUM(I12:N12)/60 -> 4.5725 | AN12: =SUM(I12:J12)/60 -> 1.3238889 | AO12: =SUM(K12:N12)/60 -> 3.2486111 | AP12: =IFERROR(SUM(R12:U12)/AO12,0) -> 44.784536 | AQ12: =IFERROR(R12/(K12/60),0) -> 20.128818 | AR12: =IFERROR(S12/(L12/60),0) -> 38.300568 | AS12: =IFERROR(T12/(M12/60),0) -> 42.963405 | AT12: =IFERROR(U12/(N12/60),0) -> 46.498972 | AU12: =(IF(D12="EV",TAT_Crr_EV,TAT_Crr_D)*AH12*TAT_G_acc*(AK12-T12)+IF(D12="EV",TAT_Kaero_EV,TAT_Kaero_D)*((AQ12/3.6)^2*R12+(AR12/3.6)^2*S12+(AT12/3.6)^2*U12))/3600 -> 54.265635 | AV12: =(IF(D12="EV",TAT_Crr_EV,TAT_Crr_D)*AH12*TAT_G_acc+IF(D12="EV",TAT_Kaero_EV,TAT_Kaero_D)*(AS12/3.6)^2)*T12/3600 -> 6.7286428 | AW12: =AH12*AI12*S12/3600 -> 16.155097 | AX12: =AH12*TAT_G_acc*AG12/3600000 -> -0.1975625 | AY12: =AU12+MAX(0,AV12-AW12) -> 54.265635 | AZ12: =MAX(0,AX12)-TAT_Descent_Share*MAX(0,-AX12) -> -0.09878125 | BA12: =MAX(0,AW12-AV12)+(1-TAT_Descent_Share)*MAX(0,-AX12) -> 9.5252355 | BB12: =MAX(0,AY12+AW12+AZ12) -> 70.321951 | BC12: =BB12/IF(D12="EV",TAT_EtaPT_EV,TAT_EtaPT_D) -> 218.39115 | BD12: =IF(D12="EV",AJ12*AM12,AJ12*AO12/TAT_EtaEng_D) -> 75.182143 | BE12: =IF(D12="EV",0,TAT_IdleFuel_D*AN12*TAT_LHV_kWhL) -> 33.005285 | BF12: =IF(D12="EV",TAT_Regen_EV*TAT_EtaPT_EV*BA12,0) -> 0 | BG12: =BC12+BD12+BE12-BF12 -> 326.57858 | BH12: =IF(D12="EV",IF(Y12="","",Y12),IF(Z12="","",Z12*TAT_LHV_kWhL)) | BI12: =IF(TAT_Cal_Apply="Yes",IF(D12="EV",TAT_CF_EV,TAT_CF_D),1) -> 1 | BJ12: =BG12*BI12 -> 326.57858 | BK12: =BJ12*3.6 -> 1175.6829 | BL12: =IF(D12="EV","",BJ12/TAT_LHV_kWhL) -> 32.748827 | BM12: =IF(D12="EV",BJ12/TAT_EtaCharger,"") | BN12: =IFERROR(BJ12/AK12,"") -> 2.2047437 | BO12: =IFERROR(AK12/BJ12,"") -> 0.45356747 | BP12: =IF(D12="EV","",IFERROR(AK12/BL12,"")) -> 4.5230756 | BQ12: =IFERROR(BB12/BJ12,"") -> 0.21532934 | BR12: =IF(D12="EV",BM12*TAT_Tariff_EV,BL12*TAT_Price_Diesel) -> 3012.8921 | BS12: =IF(D12="EV",BM12*TAT_EF_Grid,BL12*TAT_EF_Diesel) -> 87.766856 | BT12: =IFERROR(BR12/AK12,"") -> 20.340142 | BU12: =IFERROR(BS12/AK12,"") -> 0.59251718 | BV12: =IF(AND(ISNUMBER(BH12),BH12>0),BG12/BH12-1,"") | BW12: =IF(AND(AF12=1,D12="EV"),BN12,NA()) -> #N/A | BX12: =IF(AND(AF12=1,D12="Diesel"),BN12,NA()) -> #N/A
A13: PAIR_005_EV | B13: PAIR_005 | C13: 46218 | D13: EV | E13: Chennai ↔ Pondicherry | F13: Chennai → Pondicherry | G13: 0.4141088 | H13: 0 | I13: 25.883333 | J13: 4.9333333 | K13: 5.9333333 | L13: 52.333333 | M13: 37.574967 | N13: 82.933617 | O13: 0 | P13: 0.35568686 | Q13: 0.46935935 | R13: 0.35650575 | S13: 43.251328 | T13: 30.282042 | U13: 66.907082 | AA13: =IF(AND(D13<>"EV",D13<>"Diesel"),"Invalid vehicle",IF(COUNTIFS(Routes[Corridor],E13,Routes[Direction],F13)=0,"Unknown route",IF(C13="","Missing date",IF(SUM(O13:U13)<=0,"No distance","OK")))) -> OK | AB13: =IF(C13="","",DATE(YEAR(C13),MONTH(C13),1)) -> 46204 | AC13: =--(COUNTIFS($C$5:C13,C13,$D$5:D13,D13,$G$5:G13,G13,$F$5:F13,F13)=1) -> 1 | AD13: =--AND(AA13="OK",OR(TAT_Sel_Basis="All pair instances",AC13=1),OR(TAT_Sel_Corridor="All",E13=TAT_Sel_Corridor),OR(TAT_Sel_DirEff="All",F13=TAT_Sel_DirEff)) -> 0 | AE13: =--AND(AA13="OK",OR(TAT_Sel_Basis="All pair instances",AC13=1),OR(TAT_Sel_Month="All",TEXT(AB13,"mmm yyyy")=TAT_Sel_Month)) -> 1 | AF13: =AD13*AE13 -> 0 | AG13: =SUMIFS(Routes[Net elevation (m)],Routes[Corridor],E13,Routes[Direction],F13) -> -5 | AH13: =IF(D13="EV",TAT_Kerb_EV,TAT_Kerb_D)+IF(V13="",TAT_Pax_Default,V13)*TAT_Pax_Mass -> 16500 | AI13: =IF(X13="",IF(D13="EV",TAT_Acc_EV,TAT_Acc_D),X13) -> 0.25 | AJ13: =IF(D13="EV",TAT_AuxBase_EV,TAT_AuxBase_D)+TAT_HVAC_k*MAX(0,IF(W13="",TAT_Temp_Default,W13)-TAT_HVAC_Tset) -> 8.1 | AK13: =SUM(O13:U13) -> 141.622 | AL13: =SUM(H13:N13)/60 -> 3.4931986 | AM13: =SUM(I13:N13)/60 -> 3.4931986 | AN13: =SUM(I13:J13)/60 -> 0.51361111 | AO13: =SUM(K13:N13)/60 -> 2.9795875 | AP13: =IFERROR(SUM(R13:U13)/AO13,0) -> 47.253842 | AQ13: =IFERROR(R13/(K13/60),0) -> 3.6051144 | AR13: =IFERROR(S13/(L13/60),0) -> 49.58751 | AS13: =IFERROR(T13/(M13/60),0) -> 48.3546 | AT13: =IFERROR(U13/(N13/60),0) -> 48.40528 | AU13: =(IF(D13="EV",TAT_Crr_EV,TAT_Crr_D)*AH13*TAT_G_acc*(AK13-T13)+IF(D13="EV",TAT_Kaero_EV,TAT_Kaero_D)*((AQ13/3.6)^2*R13+(AR13/3.6)^2*S13+(AT13/3.6)^2*U13))/3600 -> 52.777921 | AV13: =(IF(D13="EV",TAT_Crr_EV,TAT_Crr_D)*AH13*TAT_G_acc+IF(D13="EV",TAT_Kaero_EV,TAT_Kaero_D)*(AS13/3.6)^2)*T13/3600 -> 14.303246 | AW13: =AH13*AI13*S13/3600 -> 49.558813 | AX13: =AH13*TAT_G_acc*AG13/3600000 -> -0.2248125 | AY13: =AU13+MAX(0,AV13-AW13) -> 52.777921 | AZ13: =MAX(0,AX13)-TAT_Descent_Share*MAX(0,-AX13) -> -0.11240625 | BA13: =MAX(0,AW13-AV13)+(1-TAT_Descent_Share)*MAX(0,-AX13) -> 35.367974 | BB13: =MAX(0,AY13+AW13+AZ13) -> 102.22433 | BC13: =BB13/IF(D13="EV",TAT_EtaPT_EV,TAT_EtaPT_D) -> 123.25837 | BD13: =IF(D13="EV",AJ13*AM13,AJ13*AO13/TAT_EtaEng_D) -> 28.294909 | BE13: =IF(D13="EV",0,TAT_IdleFuel_D*AN13*TAT_LHV_kWhL) -> 0 | BF13: =IF(D13="EV",TAT_Regen_EV*TAT_EtaPT_EV*BA13,0) -> 17.599457 | BG13: =BC13+BD13+BE13-BF13 -> 133.95382 | BH13: =IF(D13="EV",IF(Y13="","",Y13),IF(Z13="","",Z13*TAT_LHV_kWhL)) | BI13: =IF(TAT_Cal_Apply="Yes",IF(D13="EV",TAT_CF_EV,TAT_CF_D),1) -> 1 | BJ13: =BG13*BI13 -> 133.95382 | BK13: =BJ13*3.6 -> 482.23375 | BL13: =IF(D13="EV","",BJ13/TAT_LHV_kWhL) | BM13: =IF(D13="EV",BJ13/TAT_EtaCharger,"") -> 145.60198 | BN13: =IFERROR(BJ13/AK13,"") -> 0.94585458 | BO13: =IFERROR(AK13/BJ13,"") -> 1.057245 | BP13: =IF(D13="EV","",IFERROR(AK13/BL13,"")) | BQ13: =IFERROR(BB13/BJ13,"") -> 0.76313111 | BR13: =IF(D13="EV",BM13*TAT_Tariff_EV,BL13*TAT_Price_Diesel) -> 1383.2188 | BS13: =IF(D13="EV",BM13*TAT_EF_Grid,BL13*TAT_EF_Diesel) -> 103.3774 | BT13: =IFERROR(BR13/AK13,"") -> 9.7669766 | BU13: =IFERROR(BS13/AK13,"") -> 0.72995299 | BV13: =IF(AND(ISNUMBER(BH13),BH13>0),BG13/BH13-1,"") | BW13: =IF(AND(AF13=1,D13="EV"),BN13,NA()) -> #N/A | BX13: =IF(AND(AF13=1,D13="Diesel"),BN13,NA()) -> #N/A
A14: PAIR_005_ICE | B14: PAIR_005 | C14: 46220 | D14: Diesel | E14: Chennai ↔ Pondicherry | F14: Chennai → Pondicherry | G14: 0.48878472 | H14: 0 | I14: 31.8 | J14: 0 | K14: 1.5 | L14: 30.466667 | M14: 23 | N14: 134.38333 | O14: 0 | P14: 0.2215609 | Q14: 0 | R14: 0.11647474 | S14: 21.522287 | T14: 17.072623 | U14: 102.73816 | AA14: =IF(AND(D14<>"EV",D14<>"Diesel"),"Invalid vehicle",IF(COUNTIFS(Routes[Corridor],E14,Routes[Direction],F14)=0,"Unknown route",IF(C14="","Missing date",IF(SUM(O14:U14)<=0,"No distance","OK")))) -> OK | AB14: =IF(C14="","",DATE(YEAR(C14),MONTH(C14),1)) -> 46204 | AC14: =--(COUNTIFS($C$5:C14,C14,$D$5:D14,D14,$G$5:G14,G14,$F$5:F14,F14)=1) -> 1 | AD14: =--AND(AA14="OK",OR(TAT_Sel_Basis="All pair instances",AC14=1),OR(TAT_Sel_Corridor="All",E14=TAT_Sel_Corridor),OR(TAT_Sel_DirEff="All",F14=TAT_Sel_DirEff)) -> 0 | AE14: =--AND(AA14="OK",OR(TAT_Sel_Basis="All pair instances",AC14=1),OR(TAT_Sel_Month="All",TEXT(AB14,"mmm yyyy")=TAT_Sel_Month)) -> 1 | AF14: =AD14*AE14 -> 0 | AG14: =SUMIFS(Routes[Net elevation (m)],Routes[Corridor],E14,Routes[Direction],F14) -> -5 | AH14: =IF(D14="EV",TAT_Kerb_EV,TAT_Kerb_D)+IF(V14="",TAT_Pax_Default,V14)*TAT_Pax_Mass -> 14500 | AI14: =IF(X14="",IF(D14="EV",TAT_Acc_EV,TAT_Acc_D),X14) -> 0.25 | AJ14: =IF(D14="EV",TAT_AuxBase_EV,TAT_AuxBase_D)+TAT_HVAC_k*MAX(0,IF(W14="",TAT_Temp_Default,W14)-TAT_HVAC_Tset) -> 8.1 | AK14: =SUM(O14:U14) -> 141.6711 | AL14: =SUM(H14:N14)/60 -> 3.6858333 | AM14: =SUM(I14:N14)/60 -> 3.6858333 | AN14: =SUM(I14:J14)/60 -> 0.53 | AO14: =SUM(K14:N14)/60 -> 3.1558333 | AP14: =IFERROR(SUM(R14:U14)/AO14,0) -> 44.821614 | AQ14: =IFERROR(R14/(K14/60),0) -> 4.6589895 | AR14: =IFERROR(S14/(L14/60),0) -> 42.385248 | AS14: =IFERROR(T14/(M14/60),0) -> 44.537278 | AT14: =IFERROR(U14/(N14/60),0) -> 45.870938 | AU14: =(IF(D14="EV",TAT_Crr_EV,TAT_Crr_D)*AH14*TAT_G_acc*(AK14-T14)+IF(D14="EV",TAT_Kaero_EV,TAT_Kaero_D)*((AQ14/3.6)^2*R14+(AR14/3.6)^2*S14+(AT14/3.6)^2*U14))/3600 -> 51.639288 | AV14: =(IF(D14="EV",TAT_Crr_EV,TAT_Crr_D)*AH14*TAT_G_acc+IF(D14="EV",TAT_Kaero_EV,TAT_Kaero_D)*(AS14/3.6)^2)*T14/3600 -> 7.0046189 | AW14: =AH14*AI14*S14/3600 -> 21.671747 | AX14: =AH14*TAT_G_acc*AG14/3600000 -> -0.1975625 | AY14: =AU14+MAX(0,AV14-AW14) -> 51.639288 | AZ14: =MAX(0,AX14)-TAT_Descent_Share*MAX(0,-AX14) -> -0.09878125 | BA14: =MAX(0,AW14-AV14)+(1-TAT_Descent_Share)*MAX(0,-AX14) -> 14.765909 | BB14: =MAX(0,AY14+AW14+AZ14) -> 73.212254 | BC14: =BB14/IF(D14="EV",TAT_EtaPT_EV,TAT_EtaPT_D) -> 227.36725 | BD14: =IF(D14="EV",AJ14*AM14,AJ14*AO14/TAT_EtaEng_D) -> 73.035 | BE14: =IF(D14="EV",0,TAT_IdleFuel_D*AN14*TAT_LHV_kWhL) -> 13.213194 | BF14: =IF(D14="EV",TAT_Regen_EV*TAT_EtaPT_EV*BA14,0) -> 0 | BG14: =BC14+BD14+BE14-BF14 -> 313.61544 | BH14: =IF(D14="EV",IF(Y14="","",Y14),IF(Z14="","",Z14*TAT_LHV_kWhL)) | BI14: =IF(TAT_Cal_Apply="Yes",IF(D14="EV",TAT_CF_EV,TAT_CF_D),1) -> 1 | BJ14: =BG14*BI14 -> 313.61544 | BK14: =BJ14*3.6 -> 1129.0156 | BL14: =IF(D14="EV","",BJ14/TAT_LHV_kWhL) -> 31.448902 | BM14: =IF(D14="EV",BJ14/TAT_EtaCharger,"") | BN14: =IFERROR(BJ14/AK14,"") -> 2.2136867 | BO14: =IFERROR(AK14/BJ14,"") -> 0.45173511 | BP14: =IF(D14="EV","",IFERROR(AK14/BL14,"")) -> 4.5048029 | BQ14: =IFERROR(BB14/BJ14,"") -> 0.23344595 | BR14: =IF(D14="EV",BM14*TAT_Tariff_EV,BL14*TAT_Price_Diesel) -> 2893.299 | BS14: =IF(D14="EV",BM14*TAT_EF_Grid,BL14*TAT_EF_Diesel) -> 84.283058 | BT14: =IFERROR(BR14/AK14,"") -> 20.422647 | BU14: =IFERROR(BS14/AK14,"") -> 0.5949206 | BV14: =IF(AND(ISNUMBER(BH14),BH14>0),BG14/BH14-1,"") | BW14: =IF(AND(AF14=1,D14="EV"),BN14,NA()) -> #N/A | BX14: =IF(AND(AF14=1,D14="Diesel"),BN14,NA()) -> #N/A
A15: PAIR_006_EV | B15: PAIR_006 | C15: 46220 | D15: EV | E15: Chennai ↔ Pondicherry | F15: Chennai → Pondicherry | G15: 0.3274537 | H15: 0 | I15: 30.183333 | J15: 14.291517 | K15: 2.1 | L15: 48.092233 | M15: 33.45 | N15: 93.4 | O15: 0 | P15: 0.38306582 | Q15: 2.3361161 | R15: 0.20461421 | S15: 38.63607 | T15: 26.286683 | U15: 80.361863 | AA15: =IF(AND(D15<>"EV",D15<>"Diesel"),"Invalid vehicle",IF(COUNTIFS(Routes[Corridor],E15,Routes[Direction],F15)=0,"Unknown route",IF(C15="","Missing date",IF(SUM(O15:U15)<=0,"No distance","OK")))) -> OK | AB15: =IF(C15="","",DATE(YEAR(C15),MONTH(C15),1)) -> 46204 | AC15: =--(COUNTIFS($C$5:C15,C15,$D$5:D15,D15,$G$5:G15,G15,$F$5:F15,F15)=1) -> 1 | AD15: =--AND(AA15="OK",OR(TAT_Sel_Basis="All pair instances",AC15=1),OR(TAT_Sel_Corridor="All",E15=TAT_Sel_Corridor),OR(TAT_Sel_DirEff="All",F15=TAT_Sel_DirEff)) -> 0 | AE15: =--AND(AA15="OK",OR(TAT_Sel_Basis="All pair instances",AC15=1),OR(TAT_Sel_Month="All",TEXT(AB15,"mmm yyyy")=TAT_Sel_Month)) -> 1 | AF15: =AD15*AE15 -> 0 | AG15: =SUMIFS(Routes[Net elevation (m)],Routes[Corridor],E15,Routes[Direction],F15) -> -5 | AH15: =IF(D15="EV",TAT_Kerb_EV,TAT_Kerb_D)+IF(V15="",TAT_Pax_Default,V15)*TAT_Pax_Mass -> 16500 | AI15: =IF(X15="",IF(D15="EV",TAT_Acc_EV,TAT_Acc_D),X15) -> 0.25 | AJ15: =IF(D15="EV",TAT_AuxBase_EV,TAT_AuxBase_D)+TAT_HVAC_k*MAX(0,IF(W15="",TAT_Temp_Default,W15)-TAT_HVAC_Tset) -> 8.1 | AK15: =SUM(O15:U15) -> 148.20841 | AL15: =SUM(H15:N15)/60 -> 3.6919514 | AM15: =SUM(I15:N15)/60 -> 3.6919514 | AN15: =SUM(I15:J15)/60 -> 0.7412475 | AO15: =SUM(K15:N15)/60 -> 2.9507039 | AP15: =IFERROR(SUM(R15:U15)/AO15,0) -> 49.306618 | AQ15: =IFERROR(R15/(K15/60),0) -> 5.8461203 | AR15: =IFERROR(S15/(L15/60),0) -> 48.202465 | AS15: =IFERROR(T15/(M15/60),0) -> 47.151001 | AT15: =IFERROR(U15/(N15/60),0) -> 51.624323 | AU15: =(IF(D15="EV",TAT_Crr_EV,TAT_Crr_D)*AH15*TAT_G_acc*(AK15-T15)+IF(D15="EV",TAT_Kaero_EV,TAT_Kaero_D)*((AQ15/3.6)^2*R15+(AR15/3.6)^2*S15+(AT15/3.6)^2*U15))/3600 -> 58.859931 | AV15: =(IF(D15="EV",TAT_Crr_EV,TAT_Crr_D)*AH15*TAT_G_acc+IF(D15="EV",TAT_Kaero_EV,TAT_Kaero_D)*(AS15/3.6)^2)*T15/3600 -> 12.212435 | AW15: =AH15*AI15*S15/3600 -> 44.270497 | AX15: =AH15*TAT_G_acc*AG15/3600000 -> -0.2248125 | AY15: =AU15+MAX(0,AV15-AW15) -> 58.859931 | AZ15: =MAX(0,AX15)-TAT_Descent_Share*MAX(0,-AX15) -> -0.11240625 | BA15: =MAX(0,AW15-AV15)+(1-TAT_Descent_Share)*MAX(0,-AX15) -> 32.170468 | BB15: =MAX(0,AY15+AW15+AZ15) -> 103.01802 | BC15: =BB15/IF(D15="EV",TAT_EtaPT_EV,TAT_EtaPT_D) -> 124.21538 | BD15: =IF(D15="EV",AJ15*AM15,AJ15*AO15/TAT_EtaEng_D) -> 29.904806 | BE15: =IF(D15="EV",0,TAT_IdleFuel_D*AN15*TAT_LHV_kWhL) -> 0 | BF15: =IF(D15="EV",TAT_Regen_EV*TAT_EtaPT_EV*BA15,0) -> 16.008347 | BG15: =BC15+BD15+BE15-BF15 -> 138.11184 | BH15: =IF(D15="EV",IF(Y15="","",Y15),IF(Z15="","",Z15*TAT_LHV_kWhL)) | BI15: =IF(TAT_Cal_Apply="Yes",IF(D15="EV",TAT_CF_EV,TAT_CF_D),1) -> 1 | BJ15: =BG15*BI15 -> 138.11184 | BK15: =BJ15*3.6 -> 497.20261 | BL15: =IF(D15="EV","",BJ15/TAT_LHV_kWhL) | BM15: =IF(D15="EV",BJ15/TAT_EtaCharger,"") -> 150.12156 | BN15: =IFERROR(BJ15/AK15,"") -> 0.93187582 | BO15: =IFERROR(AK15/BJ15,"") -> 1.0731044 | BP15: =IF(D15="EV","",IFERROR(AK15/BL15,"")) | BQ15: =IFERROR(BB15/BJ15,"") -> 0.74590292 | BR15: =IF(D15="EV",BM15*TAT_Tariff_EV,BL15*TAT_Price_Diesel) -> 1426.1548 | BS15: =IF(D15="EV",BM15*TAT_EF_Grid,BL15*TAT_EF_Diesel) -> 106.58631 | BT15: =IFERROR(BR15/AK15,"") -> 9.6226308 | BU15: =IFERROR(BS15/AK15,"") -> 0.71916504 | BV15: =IF(AND(ISNUMBER(BH15),BH15>0),BG15/BH15-1,"") | BW15: =IF(AND(AF15=1,D15="EV"),BN15,NA()) -> #N/A | BX15: =IF(AND(AF15=1,D15="Diesel"),BN15,NA()) -> #N/A
A16: PAIR_006_ICE | B16: PAIR_006 | C16: 46218 | D16: Diesel | E16: Chennai ↔ Pondicherry | F16: Chennai → Pondicherry | G16: 0.47248843 | H16: 0 | I16: 69.483333 | J16: 9.95 | K16: 1.7166667 | L16: 25.133333 | M16: 23.433333 | N16: 144.63333 | O16: 0 | P16: 0.83987814 | Q16: 1.7979996 | R16: 0.57590785 | S16: 16.043683 | T16: 16.779597 | U16: 112.11315 | AA16: =IF(AND(D16<>"EV",D16<>"Diesel"),"Invalid vehicle",IF(COUNTIFS(Routes[Corridor],E16,Routes[Direction],F16)=0,"Unknown route",IF(C16="","Missing date",IF(SUM(O16:U16)<=0,"No distance","OK")))) -> OK | AB16: =IF(C16="","",DATE(YEAR(C16),MONTH(C16),1)) -> 46204 | AC16: =--(COUNTIFS($C$5:C16,C16,$D$5:D16,D16,$G$5:G16,G16,$F$5:F16,F16)=1) -> 0 | AD16: =--AND(AA16="OK",OR(TAT_Sel_Basis="All pair instances",AC16=1),OR(TAT_Sel_Corridor="All",E16=TAT_Sel_Corridor),OR(TAT_Sel_DirEff="All",F16=TAT_Sel_DirEff)) -> 0 | AE16: =--AND(AA16="OK",OR(TAT_Sel_Basis="All pair instances",AC16=1),OR(TAT_Sel_Month="All",TEXT(AB16,"mmm yyyy")=TAT_Sel_Month)) -> 1 | AF16: =AD16*AE16 -> 0 | AG16: =SUMIFS(Routes[Net elevation (m)],Routes[Corridor],E16,Routes[Direction],F16) -> -5 | AH16: =IF(D16="EV",TAT_Kerb_EV,TAT_Kerb_D)+IF(V16="",TAT_Pax_Default,V16)*TAT_Pax_Mass -> 14500 | AI16: =IF(X16="",IF(D16="EV",TAT_Acc_EV,TAT_Acc_D),X16) -> 0.25 | AJ16: =IF(D16="EV",TAT_AuxBase_EV,TAT_AuxBase_D)+TAT_HVAC_k*MAX(0,IF(W16="",TAT_Temp_Default,W16)-TAT_HVAC_Tset) -> 8.1 | AK16: =SUM(O16:U16) -> 148.15022 | AL16: =SUM(H16:N16)/60 -> 4.5725 | AM16: =SUM(I16:N16)/60 -> 4.5725 | AN16: =SUM(I16:J16)/60 -> 1.3238889 | AO16: =SUM(K16:N16)/60 -> 3.2486111 | AP16: =IFERROR(SUM(R16:U16)/AO16,0) -> 44.79217 | AQ16: =IFERROR(R16/(K16/60),0) -> 20.128818 | AR16: =IFERROR(S16/(L16/60),0) -> 38.300568 | AS16: =IFERROR(T16/(M16/60),0) -> 42.963405 | AT16: =IFERROR(U16/(N16/60),0) -> 46.50926 | AU16: =(IF(D16="EV",TAT_Crr_EV,TAT_Crr_D)*AH16*TAT_G_acc*(AK16-T16)+IF(D16="EV",TAT_Kaero_EV,TAT_Kaero_D)*((AQ16/3.6)^2*R16+(AR16/3.6)^2*S16+(AT16/3.6)^2*U16))/3600 -> 54.283339 | AV16: =(IF(D16="EV",TAT_Crr_EV,TAT_Crr_D)*AH16*TAT_G_acc+IF(D16="EV",TAT_Kaero_EV,TAT_Kaero_D)*(AS16/3.6)^2)*T16/3600 -> 6.7286428 | AW16: =AH16*AI16*S16/3600 -> 16.155097 | AX16: =AH16*TAT_G_acc*AG16/3600000 -> -0.1975625 | AY16: =AU16+MAX(0,AV16-AW16) -> 54.283339 | AZ16: =MAX(0,AX16)-TAT_Descent_Share*MAX(0,-AX16) -> -0.09878125 | BA16: =MAX(0,AW16-AV16)+(1-TAT_Descent_Share)*MAX(0,-AX16) -> 9.5252355 | BB16: =MAX(0,AY16+AW16+AZ16) -> 70.339655 | BC16: =BB16/IF(D16="EV",TAT_EtaPT_EV,TAT_EtaPT_D) -> 218.44613 | BD16: =IF(D16="EV",AJ16*AM16,AJ16*AO16/TAT_EtaEng_D) -> 75.182143 | BE16: =IF(D16="EV",0,TAT_IdleFuel_D*AN16*TAT_LHV_kWhL) -> 33.005285 | BF16: =IF(D16="EV",TAT_Regen_EV*TAT_EtaPT_EV*BA16,0) -> 0 | BG16: =BC16+BD16+BE16-BF16 -> 326.63356 | BH16: =IF(D16="EV",IF(Y16="","",Y16),IF(Z16="","",Z16*TAT_LHV_kWhL)) | BI16: =IF(TAT_Cal_Apply="Yes",IF(D16="EV",TAT_CF_EV,TAT_CF_D),1) -> 1 | BJ16: =BG16*BI16 -> 326.63356 | BK16: =BJ16*3.6 -> 1175.8808 | BL16: =IF(D16="EV","",BJ16/TAT_LHV_kWhL) -> 32.754341 | BM16: =IF(D16="EV",BJ16/TAT_EtaCharger,"") | BN16: =IFERROR(BJ16/AK16,"") -> 2.2047457 | BO16: =IFERROR(AK16/BJ16,"") -> 0.45356704 | BP16: =IF(D16="EV","",IFERROR(AK16/BL16,"")) -> 4.5230714 | BQ16: =IFERROR(BB16/BJ16,"") -> 0.2153473 | BR16: =IF(D16="EV",BM16*TAT_Tariff_EV,BL16*TAT_Price_Diesel) -> 3013.3993 | BS16: =IF(D16="EV",BM16*TAT_EF_Grid,BL16*TAT_EF_Diesel) -> 87.781633 | BT16: =IFERROR(BR16/AK16,"") -> 20.340161 | BU16: =IFERROR(BS16/AK16,"") -> 0.59251774 | BV16: =IF(AND(ISNUMBER(BH16),BH16>0),BG16/BH16-1,"") | BW16: =IF(AND(AF16=1,D16="EV"),BN16,NA()) -> #N/A | BX16: =IF(AND(AF16=1,D16="Diesel"),BN16,NA()) -> #N/A
